Workbook

Sheet 内容
C2: 品番 | D2: 品名 | E2: 代表機種 | F2: 入数 | G2: 入荷数量 | H2: ケース数 | I2: パレット枚数 | J2: 端数 | K2: 1パレット | L2: 1段のケース数
A3: 46150 | B3: 26K0406 | C3: 3TG384A10122 | D3: =IFERROR(VLOOKUP($C3,Sheet1!$B:$D,2,FALSE),"") -> JPV-H100(KV)ポリカバー | E3: =IFERROR(VLOOKUP($C3,Sheet1!$B:$D,3,FALSE),"") -> JPV-H100(KV)ポリカバー | F3: =IFERROR(VLOOKUP($C3,Sheet1!$B:$E,4,FALSE),"") -> 10 | G3: 960 | H3: =IFERROR(G3/F3,"") -> 96 | I3: =IFERROR((ROUNDDOWN(H3/K3,0)),"") -> 3 | J3: =IFERROR(H3-(I3*K3),"") -> 6 | K3: =IFERROR(VLOOKUP($C3,Sheet1!$B:$F,5,FALSE),"") -> 30
C4: 3TG392A10104 | D4: =IFERROR(VLOOKUP($C4,Sheet1!$B:$D,2,FALSE),"") -> JRI-A100(KB)ポリカバー | E4: =IFERROR(VLOOKUP($C4,Sheet1!$B:$D,3,FALSE),"") -> JRI-A100(KB) | F4: =IFERROR(VLOOKUP($C4,Sheet1!$B:$E,4,FALSE),"") -> 10 | G4: 100 | H4: =IFERROR(G4/F4,"") -> 10 | I4: =IFERROR((ROUNDDOWN(H4/K4,0)),"") -> 0 | J4: =IFERROR(H4-(I4*K4),"") -> 10 | K4: =IFERROR(VLOOKUP($C4,Sheet1!$B:$F,5,FALSE),"") -> 30
C5: 3TG392A10114 | D5: =IFERROR(VLOOKUP($C5,Sheet1!$B:$D,2,FALSE),"") -> JRI-A100(W)ポリカバー | E5: =IFERROR(VLOOKUP($C5,Sheet1!$B:$D,3,FALSE),"") -> JRI-A100(W) | F5: =IFERROR(VLOOKUP($C5,Sheet1!$B:$E,4,FALSE),"") -> 10 | G5: 200 | H5: =IFERROR(G5/F5,"") -> 20 | I5: =IFERROR((ROUNDDOWN(H5/K5,0)),"") -> 0 | J5: =IFERROR(H5-(I5*K5),"") -> 20 | K5: =IFERROR(VLOOKUP($C5,Sheet1!$B:$F,5,FALSE),"") -> 30
C6: 3TG392A10141 | D6: =IFERROR(VLOOKUP($C6,Sheet1!$B:$D,2,FALSE),"") -> JRI-G100(KKB)ポリカバー | E6: =IFERROR(VLOOKUP($C6,Sheet1!$B:$D,3,FALSE),"") -> JRI-G100(KKB) | F6: =IFERROR(VLOOKUP($C6,Sheet1!$B:$E,4,FALSE),"") -> 10 | G6: 800 | H6: =IFERROR(G6/F6,"") -> 80 | I6: =IFERROR((ROUNDDOWN(H6/K6,0)),"") -> 2 | J6: =IFERROR(H6-(I6*K6),"") -> 20 | K6: =IFERROR(VLOOKUP($C6,Sheet1!$B:$F,5,FALSE),"") -> 30
C7: 3TG392A10151 | D7: =IFERROR(VLOOKUP($C7,Sheet1!$B:$D,2,FALSE),"") -> JRI-G100WOポリカバー | E7: =IFERROR(VLOOKUP($C7,Sheet1!$B:$D,3,FALSE),"") -> JRI-G100WO | F7: =IFERROR(VLOOKUP($C7,Sheet1!$B:$E,4,FALSE),"") -> 10 | G7: 2000 | H7: =IFERROR(G7/F7,"") -> 200 | I7: =IFERROR((ROUNDDOWN(H7/K7,0)),"") -> 6 | J7: =IFERROR(H7-(I7*K7),"") -> 20 | K7: =IFERROR(VLOOKUP($C7,Sheet1!$B:$F,5,FALSE),"") -> 30
C8: 3TG393A10121 | D8: =IFERROR(VLOOKUP($C8,Sheet1!$B:$D,2,FALSE),"") -> JRI-H100KKBポリカバー | E8: =IFERROR(VLOOKUP($C8,Sheet1!$B:$D,3,FALSE),"") -> JRI-H100KKB | F8: =IFERROR(VLOOKUP($C8,Sheet1!$B:$E,4,FALSE),"") -> 10 | G8: 300 | H8: =IFERROR(G8/F8,"") -> 30 | I8: =IFERROR((ROUNDDOWN(H8/K8,0)),"") -> 1 | J8: =IFERROR(H8-(I8*K8),"") -> 0 | K8: =IFERROR(VLOOKUP($C8,Sheet1!$B:$F,5,FALSE),"") -> 30
C9: 3TG383A10170 | D9: =IFERROR(VLOOKUP($C9,Sheet1!$B:$D,2,FALSE),"") -> JPV-X100(K)ポリカバー | E9: =IFERROR(VLOOKUP($C9,Sheet1!$B:$D,3,FALSE),"") -> JPV-X100(K) | F9: =IFERROR(VLOOKUP($C9,Sheet1!$B:$E,4,FALSE),"") -> 10 | G9: 2490 | H9: =IFERROR(G9/F9,"") -> 249 | I9: =IFERROR((ROUNDDOWN(H9/K9,0)),"") -> 8 | J9: =IFERROR(H9-(I9*K9),"") -> 9 | K9: =IFERROR(VLOOKUP($C9,Sheet1!$B:$F,5,FALSE),"") -> 30
C10: 3TG392P31000 | D10: =IFERROR(VLOOKUP($C10,Sheet1!$B:$D,2,FALSE),"") -> JRIAﾌｱﾂﾍﾞﾝPK | E10: =IFERROR(VLOOKUP($C10,Sheet1!$B:$D,3,FALSE),"") -> JRI | F10: =IFERROR(VLOOKUP($C10,Sheet1!$B:$E,4,FALSE),"") -> 0 | G10: 600 | H10: =IFERROR(G10/F10,"") | I10: =IFERROR((ROUNDDOWN(H10/K10,0)),"") | J10: =IFERROR(H10-(I10*K10),"") | K10: =IFERROR(VLOOKUP($C10,Sheet1!$B:$F,5,FALSE),"") -> 0
C11: 3TG392P16201 | D11: =IFERROR(VLOOKUP($C11,Sheet1!$B:$D,2,FALSE),"") -> JRIAｽﾁ-ﾑﾎ-ﾙPK1 | E11: =IFERROR(VLOOKUP($C11,Sheet1!$B:$D,3,FALSE),"") -> JRI-C | F11: =IFERROR(VLOOKUP($C11,Sheet1!$B:$E,4,FALSE),"") -> 0 | G11: 2300 | H11: =IFERROR(G11/F11,"") | I11: =IFERROR((ROUNDDOWN(H11/K11,0)),"") | J11: =IFERROR(H11-(I11*K11),"") | K11: =IFERROR(VLOOKUP($C11,Sheet1!$B:$F,5,FALSE),"") -> 0
C12: 3TG392P16300 | D12: =IFERROR(VLOOKUP($C12,Sheet1!$B:$D,2,FALSE),"") -> JRIAﾁｮｳｱﾂﾍﾞﾝPK | E12: =IFERROR(VLOOKUP($C12,Sheet1!$B:$D,3,FALSE),"") -> JRI-C | F12: =IFERROR(VLOOKUP($C12,Sheet1!$B:$E,4,FALSE),"") -> 0 | G12: 13000 | H12: =IFERROR(G12/F12,"") | I12: =IFERROR((ROUNDDOWN(H12/K12,0)),"") | J12: =IFERROR(H12-(I12*K12),"") | K12: =IFERROR(VLOOKUP($C12,Sheet1!$B:$F,5,FALSE),"") -> 0
C13: 3YM115E00101 | D13: =IFERROR(VLOOKUP($C13,Sheet1!$B:$D,2,FALSE),"") -> MA基板06 23F3N1 | E13: =IFERROR(VLOOKUP($C13,Sheet1!$B:$D,3,FALSE),"") -> IPL | F13: =IFERROR(VLOOKUP($C13,Sheet1!$B:$E,4,FALSE),"") -> 0 | G13: 540 | H13: =IFERROR(G13/F13,"") | I13: =IFERROR((ROUNDDOWN(H13/K13,0)),"") | J13: =IFERROR(H13-(I13*K13),"") | K13: =IFERROR(VLOOKUP($C13,Sheet1!$B:$F,5,FALSE),"") -> 0
C14: 3YM105E00201 | D14: =IFERROR(VLOOKUP($C14,Sheet1!$B:$D,2,FALSE),"") -> CN基板 | E14: =IFERROR(VLOOKUP($C14,Sheet1!$B:$D,3,FALSE),"") -> IPL | F14: =IFERROR(VLOOKUP($C14,Sheet1!$B:$E,4,FALSE),"") -> 0 | G14: 1260 | H14: =IFERROR(G14/F14,"") | I14: =IFERROR((ROUNDDOWN(H14/K14,0)),"") | J14: =IFERROR(H14-(I14*K14),"") | K14: =IFERROR(VLOOKUP($C14,Sheet1!$B:$F,5,FALSE),"") -> 0
C15: 3PA904A01901 | D15: =IFERROR(VLOOKUP($C15,Sheet1!$B:$D,2,FALSE),"") -> ｶﾝｾｲﾍﾞﾝ(ken) | E15: =IFERROR(VLOOKUP($C15,Sheet1!$B:$D,3,FALSE),"") -> 完成弁 | F15: =IFERROR(VLOOKUP($C15,Sheet1!$B:$E,4,FALSE),"") -> 600 | G15: 2140 | H15: =IFERROR(G15/F15,"") -> 3.5666667 | I15: =IFERROR((ROUNDDOWN(H15/K15,0)),"") | J15: =IFERROR(H15-(I15*K15),"") | K15: =IFERROR(VLOOKUP($C15,Sheet1!$B:$F,5,FALSE),"") -> 0
C16: 3TG376P00200 | D16: =IFERROR(VLOOKUP($C16,Sheet1!$B:$D,2,FALSE),"") -> JPWAﾚﾊﾞｰ(XAA) | E16: =IFERROR(VLOOKUP($C16,Sheet1!$B:$D,3,FALSE),"") -> JPW100タイプ 気高向けレバー | F16: =IFERROR(VLOOKUP($C16,Sheet1!$B:$E,4,FALSE),"") -> 300 | G16: 760 | H16: =IFERROR(G16/F16,"") -> 2.5333333 | I16: =IFERROR((ROUNDDOWN(H16/K16,0)),"") | J16: =IFERROR(H16-(I16*K16),"") | K16: =IFERROR(VLOOKUP($C16,Sheet1!$B:$F,5,FALSE),"") -> 0
D17: =IFERROR(VLOOKUP($C17,Sheet1!$B:$D,2,FALSE),"") | E17: =IFERROR(VLOOKUP($C17,Sheet1!$B:$D,3,FALSE),"") | F17: =IFERROR(VLOOKUP($C17,Sheet1!$B:$E,4,FALSE),"") | H17: =IFERROR(G17/F17,"") | I17: =IFERROR((ROUNDDOWN(H17/K17,0)),"") | J17: =IFERROR(H17-(I17*K17),"") | K17: =IFERROR(VLOOKUP($C17,Sheet1!$B:$F,5,FALSE),"")
A18: 46153 | B18: 26K0407 | C18: 3TG384A10122 | D18: =IFERROR(VLOOKUP($C18,Sheet1!$B:$D,2,FALSE),"") -> JPV-H100(KV)ポリカバー | E18: =IFERROR(VLOOKUP($C18,Sheet1!$B:$D,3,FALSE),"") -> JPV-H100(KV)ポリカバー | F18: =IFERROR(VLOOKUP($C18,Sheet1!$B:$E,4,FALSE),"") -> 10 | G18: 200 | H18: =IFERROR(G18/F18,"") -> 20 | I18: =IFERROR((ROUNDDOWN(H18/K18,0)),"") -> 0 | J18: =IFERROR(H18-(I18*K18),"") -> 20 | K18: =IFERROR(VLOOKUP($C18,Sheet1!$B:$F,5,FALSE),"") -> 30
C19: 3TG392A10141 | D19: =IFERROR(VLOOKUP($C19,Sheet1!$B:$D,2,FALSE),"") -> JRI-G100(KKB)ポリカバー | E19: =IFERROR(VLOOKUP($C19,Sheet1!$B:$D,3,FALSE),"") -> JRI-G100(KKB) | F19: =IFERROR(VLOOKUP($C19,Sheet1!$B:$E,4,FALSE),"") -> 10 | G19: 2880 | H19: =IFERROR(G19/F19,"") -> 288 | I19: =IFERROR((ROUNDDOWN(H19/K19,0)),"") -> 9 | J19: =IFERROR(H19-(I19*K19),"") -> 18 | K19: =IFERROR(VLOOKUP($C19,Sheet1!$B:$F,5,FALSE),"") -> 30
C20: 3TG383A10107 | D20: =IFERROR(VLOOKUP($C20,Sheet1!$B:$D,2,FALSE),"") -> JPV-A100(KM)ポリカバー | E20: =IFERROR(VLOOKUP($C20,Sheet1!$B:$D,3,FALSE),"") -> JPV-A100(KM)ポリカバー | F20: =IFERROR(VLOOKUP($C20,Sheet1!$B:$E,4,FALSE),"") -> 10 | G20: 770 | H20: =IFERROR(G20/F20,"") -> 77 | I20: =IFERROR((ROUNDDOWN(H20/K20,0)),"") -> 2 | J20: =IFERROR(H20-(I20*K20),"") -> 17 | K20: =IFERROR(VLOOKUP($C20,Sheet1!$B:$F,5,FALSE),"") -> 30
C21: 3TG383A10170 | D21: =IFERROR(VLOOKUP($C21,Sheet1!$B:$D,2,FALSE),"") -> JPV-X100(K)ポリカバー | E21: =IFERROR(VLOOKUP($C21,Sheet1!$B:$D,3,FALSE),"") -> JPV-X100(K) | F21: =IFERROR(VLOOKUP($C21,Sheet1!$B:$E,4,FALSE),"") -> 10 | G21: 2010 | H21: =IFERROR(G21/F21,"") -> 201 | I21: =IFERROR((ROUNDDOWN(H21/K21,0)),"") -> 6 | J21: =IFERROR(H21-(I21*K21),"") -> 21 | K21: =IFERROR(VLOOKUP($C21,Sheet1!$B:$F,5,FALSE),"") -> 30
C22: 3TG385A10108 | D22: =IFERROR(VLOOKUP($C22,Sheet1!$B:$D,2,FALSE),"") -> JPV-A180(KM)ポリカバー | E22: =IFERROR(VLOOKUP($C22,Sheet1!$B:$D,3,FALSE),"") -> JPV-A180(KM)ポリカバー | F22: =IFERROR(VLOOKUP($C22,Sheet1!$B:$E,4,FALSE),"") -> 10 | G22: 420 | H22: =IFERROR(G22/F22,"") -> 42 | I22: =IFERROR((ROUNDDOWN(H22/K22,0)),"") -> 1 | J22: =IFERROR(H22-(I22*K22),"") -> 12 | K22: =IFERROR(VLOOKUP($C22,Sheet1!$B:$F,5,FALSE),"") -> 30
C23: 3TG396P10300 | D23: =IFERROR(VLOOKUP($C23,Sheet1!$B:$D,2,FALSE),"") -> JRICﾎｳﾈﾂｲﾀC | E23: =IFERROR(VLOOKUP($C23,Sheet1!$B:$D,3,FALSE),"") -> JRI-C | F23: =IFERROR(VLOOKUP($C23,Sheet1!$B:$E,4,FALSE),"") -> 120 | G23: 1289 | H23: =IFERROR(G23/F23,"") -> 10.741667 | I23: =IFERROR((ROUNDDOWN(H23/K23,0)),"") | J23: =IFERROR(H23-(I23*K23),"") | K23: =IFERROR(VLOOKUP($C23,Sheet1!$B:$F,5,FALSE),"") -> 0
C24: 3TG396P13000 | D24: =IFERROR(VLOOKUP($C24,Sheet1!$B:$D,2,FALSE),"") -> JRICｱﾂﾘｮｸﾊﾞﾙﾌﾞUPKCHKH | E24: =IFERROR(VLOOKUP($C24,Sheet1!$B:$D,3,FALSE),"") -> JRI-C | F24: =IFERROR(VLOOKUP($C24,Sheet1!$B:$E,4,FALSE),"") -> 0 | G24: 13000 | H24: =IFERROR(G24/F24,"") | I24: =IFERROR((ROUNDDOWN(H24/K24,0)),"") | J24: =IFERROR(H24-(I24*K24),"") | K24: =IFERROR(VLOOKUP($C24,Sheet1!$B:$F,5,FALSE),"") -> 0
C25: 3TG392P30500 | D25: =IFERROR(VLOOKUP($C25,Sheet1!$B:$D,2,FALSE),"") -> JRIAｳﾁﾌﾀｶﾊﾞｰPK | E25: =IFERROR(VLOOKUP($C25,Sheet1!$B:$D,3,FALSE),"") -> JRI | F25: =IFERROR(VLOOKUP($C25,Sheet1!$B:$E,4,FALSE),"") -> 1600 | G25: 10000 | H25: =IFERROR(G25/F25,"") -> 6.25 | I25: =IFERROR((ROUNDDOWN(H25/K25,0)),"") | J25: =IFERROR(H25-(I25*K25),"") | K25: =IFERROR(VLOOKUP($C25,Sheet1!$B:$F,5,FALSE),"") -> 0
C26: 3TG396P16500 | D26: =IFERROR(VLOOKUP($C26,Sheet1!$B:$D,2,FALSE),"") -> JRICｽﾁｰﾑﾊﾟｲﾌﾟHKH | E26: =IFERROR(VLOOKUP($C26,Sheet1!$B:$D,3,FALSE),"") -> JRI-C | F26: =IFERROR(VLOOKUP($C26,Sheet1!$B:$E,4,FALSE),"") -> 0 | G26: 13000 | H26: =IFERROR(G26/F26,"") | I26: =IFERROR((ROUNDDOWN(H26/K26,0)),"") | J26: =IFERROR(H26-(I26*K26),"") | K26: =IFERROR(VLOOKUP($C26,Sheet1!$B:$F,5,FALSE),"") -> 0
C27: 3PA131P03400 | D27: =IFERROR(VLOOKUP($C27,Sheet1!$B:$D,2,FALSE),"") -> ﾘﾝｸB | E27: =IFERROR(VLOOKUP($C27,Sheet1!$B:$D,3,FALSE),"") -> リンクB | F27: =IFERROR(VLOOKUP($C27,Sheet1!$B:$E,4,FALSE),"") -> 10000 | G27: 970 | H27: =IFERROR(G27/F27,"") -> 0.097 | I27: =IFERROR((ROUNDDOWN(H27/K27,0)),"") | J27: =IFERROR(H27-(I27*K27),"") | K27: =IFERROR(VLOOKUP($C27,Sheet1!$B:$F,5,FALSE),"") -> 0
C28: 3YM105P02100 | D28: =IFERROR(VLOOKUP($C28,Sheet1!$B:$D,2,FALSE),"") -> ｺﾈｸﾀｰ | E28: =IFERROR(VLOOKUP($C28,Sheet1!$B:$D,3,FALSE),"") -> IPL | F28: =IFERROR(VLOOKUP($C28,Sheet1!$B:$E,4,FALSE),"") -> 2594 | G28: 11013 | H28: =IFERROR(G28/F28,"") -> 4.2455667 | I28: =IFERROR((ROUNDDOWN(H28/K28,0)),"") | J28: =IFERROR(H28-(I28*K28),"") | K28: =IFERROR(VLOOKUP($C28,Sheet1!$B:$F,5,FALSE),"") -> 0
C29: 3YM105E00201 | D29: =IFERROR(VLOOKUP($C29,Sheet1!$B:$D,2,FALSE),"") -> CN基板 | E29: =IFERROR(VLOOKUP($C29,Sheet1!$B:$D,3,FALSE),"") -> IPL | F29: =IFERROR(VLOOKUP($C29,Sheet1!$B:$E,4,FALSE),"") -> 0 | G29: 787 | H29: =IFERROR(G29/F29,"") | I29: =IFERROR((ROUNDDOWN(H29/K29,0)),"") | J29: =IFERROR(H29-(I29*K29),"") | K29: =IFERROR(VLOOKUP($C29,Sheet1!$B:$F,5,FALSE),"") -> 0
C30: 3YM105E02900 | D30: =IFERROR(VLOOKUP($C30,Sheet1!$B:$D,2,FALSE),"") -> MA-CNｹｰﾌﾞﾙ | E30: =IFERROR(VLOOKUP($C30,Sheet1!$B:$D,3,FALSE),"") -> IPL | F30: =IFERROR(VLOOKUP($C30,Sheet1!$B:$E,4,FALSE),"") -> 0 | G30: 7200 | H30: =IFERROR(G30/F30,"") | I30: =IFERROR((ROUNDDOWN(H30/K30,0)),"") | J30: =IFERROR(H30-(I30*K30),"") | K30: =IFERROR(VLOOKUP($C30,Sheet1!$B:$F,5,FALSE),"") -> 0
... C38: 3TG379P10301 | D38: =IFERROR(VLOOKUP($C38,Sheet1!$B:$D,2,FALSE),"") -> JPWAﾎｳﾈﾂｲﾀM1 | E38: =IFERROR(VLOOKUP($C38,Sheet1!$B:$D,3,FALSE),"") -> JPW180タイプ ホウネツイタ | F38: =IFERROR(VLOOKUP($C38,Sheet1!$B:$E,4,FALSE),"") -> 120 | G38: 950 | H38: =IFERROR(G38/F38,"") -> 7.9166667 | I38: =IFERROR((ROUNDDOWN(H38/K38,0)),"") | J38: =IFERROR(H38-(I38*K38),"") | K38: =IFERROR(VLOOKUP($C38,Sheet1!$B:$F,5,FALSE),"") -> 0
D39: =IFERROR(VLOOKUP($C39,Sheet1!$B:$D,2,FALSE),"") | E39: =IFERROR(VLOOKUP($C39,Sheet1!$B:$D,3,FALSE),"") | F39: =IFERROR(VLOOKUP($C39,Sheet1!$B:$E,4,FALSE),"") | H39: =IFERROR(G39/F39,"") | I39: =IFERROR((ROUNDDOWN(H39/K39,0)),"") | J39: =IFERROR(H39-(I39*K39),"") | K39: =IFERROR(VLOOKUP($C39,Sheet1!$B:$F,5,FALSE),"")
D40: =IFERROR(VLOOKUP($C40,Sheet1!$B:$D,2,FALSE),"") | E40: =IFERROR(VLOOKUP($C40,Sheet1!$B:$D,3,FALSE),"") | F40: =IFERROR(VLOOKUP($C40,Sheet1!$B:$E,4,FALSE),"") | H40: =IFERROR(G40/F40,"") | I40: =IFERROR((ROUNDDOWN(H40/K40,0)),"") | J40: =IFERROR(H40-(I40*K40),"") | K40: =IFERROR(VLOOKUP($C40,Sheet1!$B:$F,5,FALSE),"")
D41: =IFERROR(VLOOKUP($C41,Sheet1!$B:$D,2,FALSE),"") | E41: =IFERROR(VLOOKUP($C41,Sheet1!$B:$D,3,FALSE),"") | F41: =IFERROR(VLOOKUP($C41,Sheet1!$B:$E,4,FALSE),"") | H41: =IFERROR(G41/F41,"") | I41: =IFERROR((ROUNDDOWN(H41/K41,0)),"") | J41: =IFERROR(H41-(I41*K41),"") | K41: =IFERROR(VLOOKUP($C41,Sheet1!$B:$F,5,FALSE),"")
D42: =IFERROR(VLOOKUP($C42,Sheet1!$B:$D,2,FALSE),"") | E42: =IFERROR(VLOOKUP($C42,Sheet1!$B:$D,3,FALSE),"") | F42: =IFERROR(VLOOKUP($C42,Sheet1!$B:$E,4,FALSE),"") | H42: =IFERROR(G42/F42,"") | I42: =IFERROR((ROUNDDOWN(H42/K42,0)),"") | J42: =IFERROR(H42-(I42*K42),"") | K42: =IFERROR(VLOOKUP($C42,Sheet1!$B:$F,5,FALSE),"")
D43: =IFERROR(VLOOKUP($C43,Sheet1!$B:$D,2,FALSE),"") | E43: =IFERROR(VLOOKUP($C43,Sheet1!$B:$D,3,FALSE),"") | F43: =IFERROR(VLOOKUP($C43,Sheet1!$B:$E,4,FALSE),"") | H43: =IFERROR(G43/F43,"") | I43: =IFERROR((ROUNDDOWN(H43/K43,0)),"") | J43: =IFERROR(H43-(I43*K43),"") | K43: =IFERROR(VLOOKUP($C43,Sheet1!$B:$F,5,FALSE),"")
D44: =IFERROR(VLOOKUP($C44,Sheet1!$B:$D,2,FALSE),"") | E44: =IFERROR(VLOOKUP($C44,Sheet1!$B:$D,3,FALSE),"") | F44: =IFERROR(VLOOKUP($C44,Sheet1!$B:$E,4,FALSE),"") | H44: =IFERROR(G44/F44,"") | I44: =IFERROR((ROUNDDOWN(H44/K44,0)),"") | J44: =IFERROR(H44-(I44*K44),"") | K44: =IFERROR(VLOOKUP($C44,Sheet1!$B:$F,5,FALSE),"")
D45: =IFERROR(VLOOKUP($C45,Sheet1!$B:$D,2,FALSE),"") | E45: =IFERROR(VLOOKUP($C45,Sheet1!$B:$D,3,FALSE),"") | F45: =IFERROR(VLOOKUP($C45,Sheet1!$B:$E,4,FALSE),"") | H45: =IFERROR(G45/F45,"") | I45: =IFERROR((ROUNDDOWN(H45/K45,0)),"") | J45: =IFERROR(H45-(I45*K45),"") | K45: =IFERROR(VLOOKUP($C45,Sheet1!$B:$F,5,FALSE),"")
D46: =IFERROR(VLOOKUP($C46,Sheet1!$B:$D,2,FALSE),"") | E46: =IFERROR(VLOOKUP($C46,Sheet1!$B:$D,3,FALSE),"") | F46: =IFERROR(VLOOKUP($C46,Sheet1!$B:$E,4,FALSE),"") | H46: =IFERROR(G46/F46,"") | I46: =IFERROR((ROUNDDOWN(H46/K46,0)),"") | J46: =IFERROR(H46-(I46*K46),"") | K46: =IFERROR(VLOOKUP($C46,Sheet1!$B:$F,5,FALSE),"")
D47: =IFERROR(VLOOKUP($C47,Sheet1!$B:$D,2,FALSE),"") | E47: =IFERROR(VLOOKUP($C47,Sheet1!$B:$D,3,FALSE),"") | F47: =IFERROR(VLOOKUP($C47,Sheet1!$B:$E,4,FALSE),"") | H47: =IFERROR(G47/F47,"") | I47: =IFERROR((ROUNDDOWN(H47/K47,0)),"") | J47: =IFERROR(H47-(I47*K47),"") | K47: =IFERROR(VLOOKUP($C47,Sheet1!$B:$F,5,FALSE),"")
D48: =IFERROR(VLOOKUP($C48,Sheet1!$B:$D,2,FALSE),"") | E48: =IFERROR(VLOOKUP($C48,Sheet1!$B:$D,3,FALSE),"") | F48: =IFERROR(VLOOKUP($C48,Sheet1!$B:$E,4,FALSE),"") | H48: =IFERROR(G48/F48,"") | I48: =IFERROR((ROUNDDOWN(H48/K48,0)),"") | J48: =IFERROR(H48-(I48*K48),"") | K48: =IFERROR(VLOOKUP($C48,Sheet1!$B:$F,5,FALSE),"")
...

Sheet Sheet1
B1: 3TG354A10112 | C1: JPK-H100(K)ポリカバー | D1: JPK-H100(K)ポリカバー | E1: 10 | F1: 35
B2: 3TG356A10114 | C2: JPK-H180(K)ポリカバー | D2: JPK-H180(K)ポリカバー | E2: 10 | F2: 35
B3: 3TG383A10107 | C3: JPV-A100(KM)ポリカバー | D3: JPV-A100(KM)ポリカバー | E3: 10 | F3: 30
B4: 3TG383A10117 | C4: JPV-A100(WM)ポリカバー | D4: JPV-A100(WM)ポリカバー | E4: 10 | F4: 30
B5: 3TG384A10122 | C5: JPV-H100(KV)ポリカバー | D5: JPV-H100(KV)ポリカバー | E5: 10 | F5: 30
B6: 3TG385A10108 | C6: JPV-A180(KM)ポリカバー | D6: JPV-A180(KM)ポリカバー | E6: 10 | F6: 30
B7: 3TG386A10123 | C7: JPV-H180(KV)ポリカバー | D7: JPV-H180(KV)ポリカバー | E7: 10 | F7: 30
B8: 3TG353A10102 | C8: JPK-A100(W)ポリカバー | D8: JPK-A100(W)ポリカバー | E8: 10 | F8: 35
B9: 3TG355A10102 | C9: JPK-A180(W)ポリカバー | D9: JPK-A180(W)ポリカバー | E9: 10 | F9: 35
B10: 3TG354A10102 | C10: JPK-B100(T)ポリカバー | D10: JPK-B100(T)ポリカバー | E10: 10 | F10: 35
B11: 3TG356A10102 | C11: JPK-B180(T)ポリカバー | D11: JPK-B180(T)ポリカバー | E11: 10 | F11: 35
B12: 3TG353A10140 | C12: JPK-S100(TD)ポリカバー | D12: JPK-S100(TD)ポリカバー | E12: 10 | F12: 35
... B46: 3TG364A10131 | C46: JPT+H10R(WS)ポリカバー | D46: JPT+H10R(WS)ポリカバー | E46: 12 | F46: 35
B47: 3TG383P00200 | C47: JPVAﾌﾀﾚﾊﾞ-(XAA) | D47: JPVAﾌﾀﾚﾊﾞ-(XAA) | E47: 300
B48: 3TG384P00200 | C48: JPVAﾌﾀﾚﾊﾞ-(HJJ) | D48: JPVBﾌﾀﾚﾊﾞ-(HJJ) | E48: 300
B49: 3TG384P00210 | C49: JPVAﾌﾀﾚﾊﾞ-(KHM) | D49: JPVCﾌﾀﾚﾊﾞ-(KHM) | E49: 300
B50: 3TG384P00220 | C50: JPVAﾌﾀﾚﾊﾞ-KJD | D50: JPVHﾌﾀﾚﾊﾞ- | E50: 300
B51: 3TG390P11400 | C51: JRXTｽﾄｯﾊﾟｰC | D51: JRXストッパー | E51: 100
B52: 3TG390P40400 | C52: JRXTｽﾄｯﾊﾟｰﾎｷｮｳｲﾀC | D52: JRX補強板 | E52: 100
B53: 3TG390P10300 | C53: JRXTﾎｳﾈﾂｲﾀC | D53: JRX060ホウネツイタ | E53: 120
B54: 3TG376P00200 | C54: JPWAﾚﾊﾞｰ(XAA) | D54: JPW100タイプ 気高向けレバー | E54: 300
B55: 3TG376P90200 | C55: JPWAﾚﾊﾞｰ(XAA) | D55: JPW100タイプ タイガー向けレバー | E55: 300
B56: 3TG376P90310 | C56: JPWAﾎｳﾈﾂｲﾀSZC | D56: JPW+T10C | E56: 240
B57: 3TG380P10330 | C57: JPWAﾎｳﾈﾂｲﾀMZC | D57: JPW+T18C | E57: 120
B58: 3TG376P90300 | C58: JPWAﾎｳﾈﾂｲﾀS | D58: JPW100タイプ ホウネツイタ | E58: 240
... B61: 3PA150P00500 | C61: ﾌﾀﾎｳﾈﾂﾊﾞﾝ | D61: SR-FCC188放熱板 | E61: 120
B62: 3PA143A00300 | C62: ｶﾝｾｲｿﾄﾌﾞﾀｶﾊﾞｰ(KK) | D62: SR-JW057(K) | E62: 16 | F62: 25
B63: 3PA143A00310 | C63: ｶﾝｾｲｿﾄﾌﾞﾀｶﾊﾞｰ(W) | D63: SR-JW057(W) | E63: 16 | F63: 25
B64: 3PA131P03400 | C64: ﾘﾝｸB | D64: リンクB | E64: 10000
B65: 3PA904A01901 | C65: ｶﾝｾｲﾍﾞﾝ(ken) | D65: 完成弁 | E65: 600
B66: 3PA912P01000 | C66: ｾﾞﾂｴﾝｼｰﾄA | D66: ゼツエンシートMPW180 | E66: 1800
B67: 3PA911P01000 | C67: ｾﾞﾂｴﾝｼｰﾄA | D67: ゼツエンシートVSX180 | E67: 600
B68: 3TG137K00820 | C68: PDRS30SﾊｺZSC | D68: PDRS30SﾊｺZSC | E68: 40
B69: 3TG138K00821 | C69: PDRS40SﾊｺZSC | D69: PDRS40SﾊｺZSC | E69: 40
B70: 3TG138K00831 | C70: PDRS40WﾊｺZWC | D70: PDRS40WﾊｺZWC | E70: 40
B71: 3TG137K00831 | C71: PDRS30WﾊｺZWC | D71: PDRS30WﾊｺZWC | E71: 40
B72: 3TG137K00802 | C72: PDRS30RﾊｺX1C | D72: PDRS30RﾊｺX1C | E72: 40
B73: 3TG137K00841 | C73: PDRS30RﾊｺX1WU | D73: PDRS30RﾊｺX1WU | E73: 40
B74: 3TG138K00802 | C74: PDRS40RﾊｺX1C | D74: PDRS40RﾊｺX1C | E74: 40
B75: 3TG137A00120 | C75: PDRS30SﾊﾝｶﾝｾｲZS1C | D75: PDRS30SﾊﾝｶﾝｾｲZS1C | E75: 1 | F75: 100
...
